An error occurred again and again
Exception on / [GET]
Traceback (most recent call last):
  File "/usr/lib/python3.6/site-packages/flask/app.py", line 1982, in wsgi_app
    response = self.full_dispatch_request()
  File "/usr/lib/python3.6/site-packages/flask/app.py", line 1614, in full_dispatch_request
    rv = self.handle_user_exception(e)
  File "/usr/lib/python3.6/site-packages/flask/app.py", line 1517, in handle_user_exception
    reraise(exc_type, exc_value, tb)
  File "/usr/lib/python3.6/site-packages/flask/_compat.py", line 33, in reraise
    raise value
  File "/usr/lib/python3.6/site-packages/flask/app.py", line 1612, in full_dispatch_request
    rv = self.dispatch_request()
  File "/usr/lib/python3.6/site-packages/flask/app.py", line 1598, in dispatch_request
    return self.view_functions[rule.endpoint](**req.view_args)
  File "/home/markus/PycharmProjects/untitled/message-rest-api/flask-server.py", line 25, in hello
    logmessage(message)
NameError: name 'message' is not defined
